Workbook

Sheet Read me
A1: Getting to school: Census 2020, primary and secondary pupils
A2: Made by Nadia Hussain, one of SkillForge's AI personas, not a real person. AI wrote this spreadsheet as an example for teachers.
A4: Question | B4: How do primary pupils in Singapore get to school, and what changes in secondary school?
A5: Source | B5: Resident Students Aged 5 Years and Over by Usual Mode of Transport to School, Level of Education Attending and Sex (Census of Population 2020), Singapore Department of Statistics, on data.gov.sg
A6: Link | B6: https://data.gov.sg/datasets/d_fc70357c97a64358829c22df30bdd423/view
A7: Licence | B7: Contains information from Resident Students Aged 5 Years and Over by Usual Mode of Transport to School, Level of Education Attending and Sex (Census of Population 2020) accessed on 24 October 2026 from data.gov.sg, which is made available under the terms of the Singapore Open Data Licence version 1.0 (https://data.gov.sg/open-data-licence).
A9: Tab | B9: What it holds
A10: Raw | B10: The file exactly as downloaded. Do not edit.
A11: Groups | B11: Each of the 11 census ways of travel, the group I put it in, and its numbers pulled from Raw with INDEX and MATCH.
A12: Clean | B12: The tidy table: one row per level and group. Numbers come from Groups with SUMIF.
A13: Summary | B13: Checks: do the groups add up to the census total? Do my numbers match the census report?
A14: Change log | B14: Every change I made, and why.
A15: Class practice (made up) | B15: A made-up class survey with mess to clean. Not real pupils. Use it to practise AVERAGE, MEDIAN, MIN and MAX.

Sheet Raw
A1: Number | B1: Total_Total | C1: Total_Males | D1: Total_Females | E1: Pre_Primary_Total | F1: Pre_Primary_Males | G1: Pre_Primary_Females | H1: Primary_Total | I1: Primary_Males | J1: Primary_Females | K1: Secondary_Total | L1: Secondary_Males | M1: Secondary_Females | N1: Post_Secondary_Non_Tertiary_Total | O1: Post_Secondary_Non_Tertiary_Males | P1: Post_Secondary_Non_Tertiary_Females | Q1: PolytechnicDiploma_Total | R1: PolytechnicDiploma_Males | S1: PolytechnicDiploma_Females | T1: ProfessionalQualificationandOtherDiploma_Total | U1: ProfessionalQualificationandOtherDiploma_Males | V1: ProfessionalQualificationandOtherDiploma_Females | W1: University_Total | X1: University_Males | Y1: University_Females
A2: Total | B2: 715209 | C2: 361536 | D2: 353673 | E2: 55855 | F2: 28872 | G2: 26984 | H2: 245456 | I2: 125817 | J2: 119638 | K2: 173710 | L2: 88302 | M2: 85409 | N2: 56360 | O2: 29919 | P2: 26441 | Q2: 72608 | R2: 37780 | S2: 34828 | T2: 11376 | U2: 5242 | V2: 6134 | W2: 99844 | X2: 45605 | Y2: 54239
A3: Public Bus Only | B3: 157002 | C3: 79414 | D3: 77588 | E3: 6093 | F3: 3167 | G3: 2926 | H3: 38560 | I3: 19403 | J3: 19157 | K3: 64080 | L3: 32945 | M3: 31136 | N3: 14542 | O3: 8219 | P3: 6323 | Q3: 17629 | R3: 8696 | S3: 8933 | T3: 2290 | U3: 1142 | V3: 1148 | W3: 13808 | X3: 5842 | Y3: 7966
A4: Rail (MRT/LRT) Only | B4: 54685 | C4: 28182 | D4: 26503 | E4: 710 | F4: 315 | G4: 396 | H4: 3960 | I4: 2127 | J4: 1833 | K4: 13238 | L4: 7216 | M4: 6022 | N4: 7019 | O4: 3647 | P4: 3372 | Q4: 12067 | R4: 6715 | S4: 5352 | T4: 1880 | U4: 692 | V4: 1188 | W4: 15811 | X4: 7471 | Y4: 8340
A5: Rail (MRT/LRT) & Public Bus Only | B5: 171218 | C5: 83683 | D5: 87535 | E5: 1044 | F5: 587 | G5: 457 | H5: 7333 | I5: 3627 | J5: 3706 | K5: 40809 | L5: 20477 | M5: 20332 | N5: 26415 | O5: 13795 | P5: 12620 | Q5: 37187 | R5: 18881 | S5: 18306 | T5: 5702 | U5: 2721 | V5: 2981 | W5: 52729 | X5: 23595 | Y5: 29134
A6: Combination of Rail (MRT/LRT) and/or Public Bus, with Other Modes | B6: 7946 | C6: 4190 | D6: 3756 | E6: 387 | F6: 234 | G6: 154 | H6: 2518 | I6: 1370 | J6: 1147 | K6: 2665 | L6: 1450 | M6: 1214 | N6: 602 | O6: 259 | P6: 343 | Q6: 594 | R6: 319 | S6: 274 | T6: 87 | U6: 57 | V6: 29 | W6: 1094 | X6: 499 | Y6: 595
A7: Taxi/Private Hire Car Only | B7: 4806 | C7: 2440 | D7: 2366 | E7: 662 | F7: 408 | G7: 255 | H7: 1797 | I7: 909 | J7: 887 | K7: 989 | L7: 410 | M7: 578 | N7: 282 | O7: 200 | P7: 82 | Q7: 136 | R7: 69 | S7: 67 | T7: 91 | U7: 23 | V7: 68 | W7: 850 | X7: 421 | Y7: 429
A8: Car Only | B8: 96498 | C8: 47993 | D8: 48505 | E8: 12378 | F8: 6340 | G8: 6037 | H8: 51709 | I8: 26411 | J8: 25298 | K8: 21531 | L8: 10128 | M8: 11403 | N8: 4394 | O8: 1848 | P8: 2547 | Q8: 1241 | R8: 740 | S8: 501 | T8: 308 | U8: 132 | V8: 176 | W8: 4937 | X8: 2394 | Y8: 2543
A9: Private Chartered Bus/Van Only | B9: 44046 | C9: 22336 | D9: 21710 | E9: 5308 | F9: 2739 | G9: 2569 | H9: 33842 | I9: 17184 | J9: 16658 | K9: 4061 | L9: 2007 | M9: 2054 | N9: 461 | O9: 203 | P9: 258 | Q9: 75 | R9: 41 | S9: 34 | T9: 16 | U9: 7 | V9: 9 | W9: 283 | X9: 155 | Y9: 128
A10: Lorry/Pickup Only | B10: 964 | C10: 455 | D10: 509 | E10: 132 | F10: 107 | G10: 25 | H10: 542 | I10: 226 | J10: 316 | K10: 242 | L10: 105 | M10: 137 | N10: - | O10: - | P10: - | Q10: 35 | R10: 17 | S10: 17 | T10: 13 | U10: - | V10: 13 | W10: - | X10: - | Y10: -
A11: Motorcycle/Scooter Only | B11: 3134 | C11: 2583 | D11: 551 | E11: 69 | F11: 51 | G11: 17 | H11: 561 | I11: 291 | J11: 270 | K11: 228 | L11: 126 | M11: 102 | N11: 514 | O11: 503 | P11: 11 | Q11: 730 | R11: 627 | S11: 103 | T11: 124 | U11: 110 | V11: 14 | W11: 909 | X11: 875 | Y11: 34
A12: Others | B12: 5866 | C12: 3118 | D12: 2748 | E12: 996 | F12: 479 | G12: 516 | H12: 3278 | I12: 1547 | J12: 1731 | K12: 932 | L12: 696 | M12: 236 | N12: 191 | O12: 128 | P12: 62 | Q12: 117 | R12: 75 | S12: 41 | T12: 21 | U12: 12 | V12: 10 | W12: 331 | X12: 181 | Y12: 151
A13: No Transport Required | B13: 169044 | C13: 87143 | D13: 81901 | E13: 28077 | F13: 14446 | G13: 13631 | H13: 101356 | I13: 52721 | J13: 48635 | K13: 24935 | L13: 12741 | M13: 12194 | N13: 1941 | O13: 1117 | P13: 824 | Q13: 2798 | R13: 1599 | S13: 1199 | T13: 845 | U13: 347 | V13: 498 | W13: 9093 | X13: 4173 | Y13: 4919

Sheet Groups
A1: Census way of travel | B1: My group | C1: Primary pupils | D1: Secondary pupils
A2: Public Bus Only | B2: Public bus | C2: =INDEX(Raw!$H$1:$H$13,MATCH($A2,Raw!$A$1:$A$13,0)) | D2: =INDEX(Raw!$K$1:$K$13,MATCH($A2,Raw!$A$1:$A$13,0))
A3: Rail (MRT/LRT) Only | B3: MRT or LRT, with or without a bus | C3: =INDEX(Raw!$H$1:$H$13,MATCH($A3,Raw!$A$1:$A$13,0)) | D3: =INDEX(Raw!$K$1:$K$13,MATCH($A3,Raw!$A$1:$A$13,0))
A4: Rail (MRT/LRT) & Public Bus Only | B4: MRT or LRT, with or without a bus | C4: =INDEX(Raw!$H$1:$H$13,MATCH($A4,Raw!$A$1:$A$13,0)) | D4: =INDEX(Raw!$K$1:$K$13,MATCH($A4,Raw!$A$1:$A$13,0))
A5: Combination of Rail (MRT/LRT) and/or Public Bus, with Other Modes | B5: MRT or LRT, with or without a bus | C5: =INDEX(Raw!$H$1:$H$13,MATCH($A5,Raw!$A$1:$A$13,0)) | D5: =INDEX(Raw!$K$1:$K$13,MATCH($A5,Raw!$A$1:$A$13,0))
A6: Taxi/Private Hire Car Only | B6: Car, taxi or private-hire car | C6: =INDEX(Raw!$H$1:$H$13,MATCH($A6,Raw!$A$1:$A$13,0)) | D6: =INDEX(Raw!$K$1:$K$13,MATCH($A6,Raw!$A$1:$A$13,0))
A7: Car Only | B7: Car, taxi or private-hire car | C7: =INDEX(Raw!$H$1:$H$13,MATCH($A7,Raw!$A$1:$A$13,0)) | D7: =INDEX(Raw!$K$1:$K$13,MATCH($A7,Raw!$A$1:$A$13,0))
A8: Private Chartered Bus/Van Only | B8: School bus or van | C8: =INDEX(Raw!$H$1:$H$13,MATCH($A8,Raw!$A$1:$A$13,0)) | D8: =INDEX(Raw!$K$1:$K$13,MATCH($A8,Raw!$A$1:$A$13,0))
A9: Lorry/Pickup Only | B9: Other ways | C9: =INDEX(Raw!$H$1:$H$13,MATCH($A9,Raw!$A$1:$A$13,0)) | D9: =INDEX(Raw!$K$1:$K$13,MATCH($A9,Raw!$A$1:$A$13,0))
A10: Motorcycle/Scooter Only | B10: Other ways | C10: =INDEX(Raw!$H$1:$H$13,MATCH($A10,Raw!$A$1:$A$13,0)) | D10: =INDEX(Raw!$K$1:$K$13,MATCH($A10,Raw!$A$1:$A$13,0))
A11: Others | B11: Other ways | C11: =INDEX(Raw!$H$1:$H$13,MATCH($A11,Raw!$A$1:$A$13,0)) | D11: =INDEX(Raw!$K$1:$K$13,MATCH($A11,Raw!$A$1:$A$13,0))
A12: No Transport Required | B12: No transport needed | C12: =INDEX(Raw!$H$1:$H$13,MATCH($A12,Raw!$A$1:$A$13,0)) | D12: =INDEX(Raw!$K$1:$K$13,MATCH($A12,Raw!$A$1:$A$13,0))

Sheet Clean
A1: level | B1: group | C1: pupils | D1: percent_of_level
A2: Primary | B2: No transport needed | C2: =SUMIF(Groups!$B$2:$B$12,$B2,Groups!C$2:C$12) | D2: =C2/SUMIF($A$2:$A$13,$A2,$C$2:$C$13)
A3: Primary | B3: Car, taxi or private-hire car | C3: =SUMIF(Groups!$B$2:$B$12,$B3,Groups!C$2:C$12) | D3: =C3/SUMIF($A$2:$A$13,$A3,$C$2:$C$13)
A4: Primary | B4: Public bus | C4: =SUMIF(Groups!$B$2:$B$12,$B4,Groups!C$2:C$12) | D4: =C4/SUMIF($A$2:$A$13,$A4,$C$2:$C$13)
A5: Primary | B5: School bus or van | C5: =SUMIF(Groups!$B$2:$B$12,$B5,Groups!C$2:C$12) | D5: =C5/SUMIF($A$2:$A$13,$A5,$C$2:$C$13)
A6: Primary | B6: MRT or LRT, with or without a bus | C6: =SUMIF(Groups!$B$2:$B$12,$B6,Groups!C$2:C$12) | D6: =C6/SUMIF($A$2:$A$13,$A6,$C$2:$C$13)
A7: Primary | B7: Other ways | C7: =SUMIF(Groups!$B$2:$B$12,$B7,Groups!C$2:C$12) | D7: =C7/SUMIF($A$2:$A$13,$A7,$C$2:$C$13)
A8: Secondary | B8: No transport needed | C8: =SUMIF(Groups!$B$2:$B$12,$B8,Groups!D$2:D$12) | D8: =C8/SUMIF($A$2:$A$13,$A8,$C$2:$C$13)
A9: Secondary | B9: Car, taxi or private-hire car | C9: =SUMIF(Groups!$B$2:$B$12,$B9,Groups!D$2:D$12) | D9: =C9/SUMIF($A$2:$A$13,$A9,$C$2:$C$13)
A10: Secondary | B10: Public bus | C10: =SUMIF(Groups!$B$2:$B$12,$B10,Groups!D$2:D$12) | D10: =C10/SUMIF($A$2:$A$13,$A10,$C$2:$C$13)
A11: Secondary | B11: School bus or van | C11: =SUMIF(Groups!$B$2:$B$12,$B11,Groups!D$2:D$12) | D11: =C11/SUMIF($A$2:$A$13,$A11,$C$2:$C$13)
A12: Secondary | B12: MRT or LRT, with or without a bus | C12: =SUMIF(Groups!$B$2:$B$12,$B12,Groups!D$2:D$12) | D12: =C12/SUMIF($A$2:$A$13,$A12,$C$2:$C$13)
A13: Secondary | B13: Other ways | C13: =SUMIF(Groups!$B$2:$B$12,$B13,Groups!D$2:D$12) | D13: =C13/SUMIF($A$2:$A$13,$A13,$C$2:$C$13)

Sheet Summary
A1: Check | B1: My number | C1: Census number | D1: Same?
A2: Primary: my 6 groups add up to the census total | B2: =SUMIF(Clean!$A$2:$A$13,"Primary",Clean!$C$2:$C$13) | C2: =Raw!H2 | D2: =B2=C2
A3: Secondary: my 6 groups add up to the census total | B3: =SUMIF(Clean!$A$2:$A$13,"Secondary",Clean!$C$2:$C$13) | C3: =Raw!K2 | D3: =B3=C3
A4: Pre-primary and primary needing no transport (report says 43.0%) | B4: =ROUND((Raw!E13+Raw!H13)/(Raw!E2+Raw!H2)*100,1) | C4: 43 | D4: =B4=C4
A5: Pre-primary and primary going by car, taxi or private-hire car (report says 22.0%) | B5: =ROUND((Raw!E8+Raw!E7+Raw!H8+Raw!H7)/(Raw!E2+Raw!H2)*100,1) | C5: 22 | D5: =B5=C5
A6: Secondary going by public bus only (report says 36.9%) | B6: =ROUND(Raw!K3/Raw!K2*100,1) | C6: 36.9 | D6: =B6=C6
A8: Row 5 is 0.1 points off. I could not find why. It is small, so I kept going and wrote it in the change log.

Sheet Change log
A1: # | B1: What I changed, and why
A2: 1 | B2: Kept the raw file. I downloaded it from data.gov.sg on 24 October 2026. It sits in data/raw, unchanged.
A3: 2 | B3: Watched for a comma inside a label. One way of travel is "Combination of Rail (MRT/LRT) and/or Public Bus, with Other Modes". The comma sits inside quote marks. Google Sheets reads it right. Splitting the lines on commas by hand breaks that row.
A4: 3 | B4: Kept only the Total columns. My question is not about boys and girls, so I dropped the Males and Females columns.
A5: 4 | B5: Kept only Primary and Secondary. My P6 class is about to move from one to the other. I dropped the other six levels.
A6: 5 | B6: Merged 11 ways of travel into 6 groups. Groups under 1% are hard to see and add reading load. Car Only and Taxi/Private Hire Car Only became Car, taxi or private-hire car. The three rail rows became MRT or LRT, with or without a bus. Lorry/Pickup, Motorcycle/Scooter and Others became Other ways. No Transport Required became No transport needed. The Groups tab shows every row.
A7: 6 | B7: Checked that the groups add up. Primary comes to 245,456 and secondary to 173,710, the same as the census totals. Then I worked out each group as a percent of its level, to 1 decimal place.
A8: 7 | B8: Checked against the census report. Two numbers match: 43.0% of pre-primary and primary pupils needed no transport, and 36.9% of secondary pupils took a public bus only. One is 0.1 points off: I get 22.1% by car, taxi or private-hire car, and the report says 22.0%. I could not find why. It is small, so I kept going.
A9: 8 | B9: Did not mix in the travel-time table. It counts 704,383 students, not 715,209, because its footnote says it leaves out students studying from home. It also does not split primary from secondary. So I quote the report's median travel times instead: 15 minutes for pre-primary and primary, 30 minutes for secondary.

Sheet Class practice (made up)
A1: MADE-UP DATA for practice. These are not real pupils.
A2: slip | B2: how_i_travel | C2: minutes_as_written | D2: minutes_clean | E2: what_i_did
A3: 1 | B3: Walk | C3: 10 | D3: 10
A4: 2 | B4: School bus | C4: 35 min | D4: 35 | E4: Took out the word
A5: 3 | B5: Car | C5: 15 | D5: 15
A6: 4 | B6: Walk | C6: 5 | D6: 5
A7: 5 | B7: Public bus | C7: 20 | D7: 20
A8: 6 | B8: Walk | C8: 8 | D8: 8
A9: 7 | B9: School bus | C9: abt 30 | D9: 30 | E9: Took out the word
A10: 8 | B10: Car | C10: 10 | D10: 10
A11: 9 | B11: Walk | C11: 5 to 10 | D11: 7.5 | E11: A range: used the middle
A12: 10 | B12: Public bus | C12: 25 | D12: 25
A13: 11 | B13: MRT and bus | C13: 45 | D13: 45
A14: 12 | B14: Walk | C14: 12 | D14: 12
A15: 12 | B15: Walk | C15: 12 | E15: Slip 12 typed twice: not counted
A16: 13 | B16: School bus | C16: 40 | D16: 40
A17: 14 | B17: Car | E17: Blank: left blank
A18: 15 | B18: Walk | C18: 7 | D18: 7
A19: 16 | B19: Public bus | C19: 15 mins | D19: 15 | E19: Took out the word
A20: 17 | B20: Prefer not to say | C20: 20 | D20: 20
A21: 18 | B21: Walk | C21: 10 | D21: 10
A22: 19 | B22: School bus | C22: 200 | E22: Can't be right, can't ask: left blank
A23: 20 | B23: Car | C23: 20 | D23: 20
A24: 21 | B24: Walk | C24: half hour | D24: 30 | E24: Words to a number
A25: 22 | B25: Public bus | C25: 30 | D25: 30
A26: 23 | B26: Walk | C26: 6 | D26: 6
A27: 24 | B27: Car | C27: 12 | D27: 12
A28: 25 | B28: School bus | C28: 25 | D28: 25
A29: 26 | B29: Walk | C29: not sure | E29: Not a number: left blank
A30: 27 | B30: Public bus | C30: 18 | D30: 18
A31: 28 | B31: Walk | C31: 10 | D31: 10
A32: 29 | B32: Car | C32: 15 | D32: 15
A33: 30 | B33: Walk | C33: 5 | D33: 5
B35: How many numbers | D35: =COUNT(D3:D33)
B36: AVERAGE (mean) | D36: =ROUND(AVERAGE(D3:D33),1)
B37: MEDIAN (middle) | D37: =MEDIAN(D3:D33)
B38: MIN (shortest) | D38: =MIN(D3:D33)
B39: MAX (longest) | D39: =MAX(D3:D33)
B40: Range (longest minus shortest) | D40: =MAX(D3:D33)-MIN(D3:D33)
B42: Count by way of travel (rows with a duplicate removed)
...
